<?xml version="1.0" ?>
<!-- =================================================================================== -->
<!-- |    This document was autogenerated by xacro from robot.urdf.xacro               | -->
<!-- |    EDITING THIS FILE BY HAND IS NOT RECOMMENDED                                 | -->
<!-- =================================================================================== -->
<robot name="robot">
  <material name="Black">
    <color rgba="0.1 0.1 0.1 1.0"/>
  </material>
  <material name="Green">
    <color rgba="0.0 0.8 0.0 1.0"/>
  </material>
  <material name="aluminum">
    <color rgba="0.5 0.5 0.5 1.0"/>
  </material>
  <material name="DarkGrey">
    <color rgba="0.3 0.3 0.3 1.0"/>
  </material>
  <material name="GunMetalGrey">
    <color rgba="0.46 0.5 0.56 1.0"/>
  </material>
  <material name="Gold">
    <color rgba="1 1 0.752941176470588 1"/>
  </material>
  <material name="zedm_mat">
    <color rgba="0 0 0 0.9"/>
  </material>
  <link name="base_link">
    <visual>
      <geometry>
        <mesh filename="package://r2d2_description/meshes/body_print.stl" scale="0.008 0.008 0.008"/>
        <color name="blue"/>
      </geometry>
    </visual>
  </link>
  <link name="dome">
    <visual>
      <geometry>
        <mesh filename="package://r2d2_description/meshes/dome_print.stl" scale="0.008 0.008 0.008"/>
        <color name="blue"/>
      </geometry>
    </visual>
  </link>
  <joint name="neck" type="revolute">
    <parent link="base_link"/>
    <child link="dome"/>
  </joint>
</robot>
